C:\Users\jonmi\AppData\Local\Microsoft\WindowsApps\python3.12.exe C:\Users\jonmi\PycharmProjects\Comp_pokedex_python\comp_pokedex.py 
Exception in Tkinter callback
Traceback (most recent call last):
  File "C:\Users\jonmi\AppData\Local\Packages\PythonSoftwareFoundation.Python.3.12_qbz5n2kfra8p0\LocalCache\local-packages\Python312\site-packages\pypokedex\api.py", line 28, in get
    response.raise_for_status()
  File "C:\Users\jonmi\AppData\Local\Packages\PythonSoftwareFoundation.Python.3.12_qbz5n2kfra8p0\LocalCache\local-packages\Python312\site-packages\requests\models.py", line 1021, in raise_for_status
    raise HTTPError(http_error_msg, response=self)
requests.exceptions.HTTPError: 404 Client Error: Not Found for url: https://pokeapi.co/api/v2/pokemon/1%0A1

The above exception was the direct cause of the following exception:

Traceback (most recent call last):
  File "C:\Program Files\WindowsApps\PythonSoftwareFoundation.Python.3.12_3.12.752.0_x64__qbz5n2kfra8p0\Lib\tkinter\__init__.py", line 1967, in __call__
    return self.func(*args)
           ^^^^^^^^^^^^^^^^
  File "C:\Users\jonmi\PycharmProjects\Comp_pokedex_python\comp_pokedex.py", line 38, in load_pokemon
    pokemon = pypokedex.get(name=text_id_name.get(1.0, "end-1c"))
              ^^^^^^^^^^^^^^^^^^^^^^^^^^^^^^^^^^^^^^^^^^^^^^^^^^^
  File "C:\Users\jonmi\AppData\Local\Packages\PythonSoftwareFoundation.Python.3.12_qbz5n2kfra8p0\LocalCache\local-packages\Python312\site-packages\pypokedex\api.py", line 32, in get
    raise PyPokedexHTTPError(
pypokedex.exceptions.PyPokedexHTTPError: The requested pokemon was not found!
